2019-09-28 19:09:49,885 ERROR: Exception on /recipeSubmission [POST] [in /Users/timgilboy/recipes_v3/venv/lib/python3.6/site-packages/flask/app.py:1891]
Traceback (most recent call last):
  File "/Users/timgilboy/recipes_v3/venv/lib/python3.6/site-packages/sqlalchemy/engine/base.py", line 1244, in _execute_context
    cursor, statement, parameters, context
  File "/Users/timgilboy/recipes_v3/venv/lib/python3.6/site-packages/sqlalchemy/engine/default.py", line 552, in do_execute
    cursor.execute(statement, parameters)
sqlite3.InterfaceError: Error binding parameter 1 - probably unsupported type.

The above exception was the direct cause of the following exception:

Traceback (most recent call last):
  File "/Users/timgilboy/recipes_v3/venv/lib/python3.6/site-packages/flask/app.py", line 2446, in wsgi_app
    response = self.full_dispatch_request()
  File "/Users/timgilboy/recipes_v3/venv/lib/python3.6/site-packages/flask/app.py", line 1951, in full_dispatch_request
    rv = self.handle_user_exception(e)
  File "/Users/timgilboy/recipes_v3/venv/lib/python3.6/site-packages/flask/app.py", line 1820, in handle_user_exception
    reraise(exc_type, exc_value, tb)
  File "/Users/timgilboy/recipes_v3/venv/lib/python3.6/site-packages/flask/_compat.py", line 39, in reraise
    raise value
  File "/Users/timgilboy/recipes_v3/venv/lib/python3.6/site-packages/flask/app.py", line 1949, in full_dispatch_request
    rv = self.dispatch_request()
  File "/Users/timgilboy/recipes_v3/venv/lib/python3.6/site-packages/flask/app.py", line 1935, in dispatch_request
    return self.view_functions[rule.endpoint](**req.view_args)
  File "/Users/timgilboy/recipes_v3/venv/lib/python3.6/site-packages/flask_login/utils.py", line 261, in decorated_view
    return func(*args, **kwargs)
  File "/Users/timgilboy/recipes_v3/recipe-box/app/main/routes.py", line 47, in recipeSubmission
    recipePull(inputurl)
  File "/Users/timgilboy/recipes_v3/recipe-box/scrapertest.py", line 106, in recipePull
    db.session.commit()
  File "/Users/timgilboy/recipes_v3/venv/lib/python3.6/site-packages/sqlalchemy/orm/scoping.py", line 162, in do
    return getattr(self.registry(), name)(*args, **kwargs)
  File "/Users/timgilboy/recipes_v3/venv/lib/python3.6/site-packages/sqlalchemy/orm/session.py", line 1027, in commit
    self.transaction.commit()
  File "/Users/timgilboy/recipes_v3/venv/lib/python3.6/site-packages/sqlalchemy/orm/session.py", line 494, in commit
    self._prepare_impl()
  File "/Users/timgilboy/recipes_v3/venv/lib/python3.6/site-packages/sqlalchemy/orm/session.py", line 473, in _prepare_impl
    self.session.flush()
  File "/Users/timgilboy/recipes_v3/venv/lib/python3.6/site-packages/sqlalchemy/orm/session.py", line 2459, in flush
    self._flush(objects)
  File "/Users/timgilboy/recipes_v3/venv/lib/python3.6/site-packages/sqlalchemy/orm/session.py", line 2597, in _flush
    transaction.rollback(_capture_exception=True)
  File "/Users/timgilboy/recipes_v3/venv/lib/python3.6/site-packages/sqlalchemy/util/langhelpers.py", line 68, in __exit__
    compat.reraise(exc_type, exc_value, exc_tb)
  File "/Users/timgilboy/recipes_v3/venv/lib/python3.6/site-packages/sqlalchemy/util/compat.py", line 153, in reraise
    raise value
  File "/Users/timgilboy/recipes_v3/venv/lib/python3.6/site-packages/sqlalchemy/orm/session.py", line 2557, in _flush
    flush_context.execute()
  File "/Users/timgilboy/recipes_v3/venv/lib/python3.6/site-packages/sqlalchemy/orm/unitofwork.py", line 422, in execute
    rec.execute(self)
  File "/Users/timgilboy/recipes_v3/venv/lib/python3.6/site-packages/sqlalchemy/orm/unitofwork.py", line 589, in execute
    uow,
  File "/Users/timgilboy/recipes_v3/venv/lib/python3.6/site-packages/sqlalchemy/orm/persistence.py", line 245, in save_obj
    insert,
  File "/Users/timgilboy/recipes_v3/venv/lib/python3.6/site-packages/sqlalchemy/orm/persistence.py", line 1138, in _emit_insert_statements
    statement, params
  File "/Users/timgilboy/recipes_v3/venv/lib/python3.6/site-packages/sqlalchemy/engine/base.py", line 988, in execute
    return meth(self, multiparams, params)
  File "/Users/timgilboy/recipes_v3/venv/lib/python3.6/site-packages/sqlalchemy/sql/elements.py", line 287, in _execute_on_connection
    return connection._execute_clauseelement(self, multiparams, params)
  File "/Users/timgilboy/recipes_v3/venv/lib/python3.6/site-packages/sqlalchemy/engine/base.py", line 1107, in _execute_clauseelement
    distilled_params,
  File "/Users/timgilboy/recipes_v3/venv/lib/python3.6/site-packages/sqlalchemy/engine/base.py", line 1248, in _execute_context
    e, statement, parameters, cursor, context
  File "/Users/timgilboy/recipes_v3/venv/lib/python3.6/site-packages/sqlalchemy/engine/base.py", line 1466, in _handle_dbapi_exception
    util.raise_from_cause(sqlalchemy_exception, exc_info)
  File "/Users/timgilboy/recipes_v3/venv/lib/python3.6/site-packages/sqlalchemy/util/compat.py", line 398, in raise_from_cause
    reraise(type(exception), exception, tb=exc_tb, cause=cause)
  File "/Users/timgilboy/recipes_v3/venv/lib/python3.6/site-packages/sqlalchemy/util/compat.py", line 152, in reraise
    raise value.with_traceback(tb)
  File "/Users/timgilboy/recipes_v3/venv/lib/python3.6/site-packages/sqlalchemy/engine/base.py", line 1244, in _execute_context
    cursor, statement, parameters, context
  File "/Users/timgilboy/recipes_v3/venv/lib/python3.6/site-packages/sqlalchemy/engine/default.py", line 552, in do_execute
    cursor.execute(statement, parameters)
sqlalchemy.exc.InterfaceError: (sqlite3.InterfaceError) Error binding parameter 1 - probably unsupported type.
[SQL: INSERT INTO recipe__steps2 (recipe_id, directions) VALUES (?, ?)]
[parameters: (2, {'@type': 'HowToStep', 'text': 'Toss the chicken breast with garlic powder, salt, and pepper. Heat olive oil in a 10-inch skillet over medium heat. Add chicken breast and cook until browned, stirring often, about 3 minutes. Add garlic to skillet and cook for 30 seconds more.'})]
(Background on this error at: http://sqlalche.me/e/rvf5)
2019-09-28 19:11:59,817 INFO: Recipe book startup [in /Users/timgilboy/recipes_v3/recipe-box/app/__init__.py:77]
2019-09-28 19:11:59,817 INFO: Recipe book startup [in /Users/timgilboy/recipes_v3/recipe-box/app/__init__.py:77]
2019-09-28 19:11:59,818 INFO: Recipe book startup [in /Users/timgilboy/recipes_v3/recipe-box/app/__init__.py:77]
2019-09-28 19:11:59,831 INFO: Recipe book startup [in /Users/timgilboy/recipes_v3/recipe-box/app/__init__.py:77]
