2019-09-28 18:55:27,058 ERROR: Exception on /favicon.ico [GET] [in /Users/timgilboy/recipes_v3/venv/lib/python3.6/site-packages/flask/app.py:1891]
Traceback (most recent call last):
  File "/Users/timgilboy/recipes_v3/venv/lib/python3.6/site-packages/flask/app.py", line 1949, in full_dispatch_request
    rv = self.dispatch_request()
  File "/Users/timgilboy/recipes_v3/venv/lib/python3.6/site-packages/flask/app.py", line 1925, in dispatch_request
    self.raise_routing_exception(req)
  File "/Users/timgilboy/recipes_v3/venv/lib/python3.6/site-packages/flask/app.py", line 1907, in raise_routing_exception
    raise request.routing_exception
  File "/Users/timgilboy/recipes_v3/venv/lib/python3.6/site-packages/flask/ctx.py", line 350, in match_request
    result = self.url_adapter.match(return_rule=True)
  File "/Users/timgilboy/recipes_v3/venv/lib/python3.6/site-packages/werkzeug/routing.py", line 1799, in match
    raise NotFound()
werkzeug.exceptions.NotFound: 404 Not Found: The requested URL was not found on the server. If you entered the URL manually please check your spelling and try again.

During handling of the above exception, another exception occurred:

Traceback (most recent call last):
  File "/Users/timgilboy/recipes_v3/venv/lib/python3.6/site-packages/sqlalchemy/orm/relationships.py", line 2346, in _determine_joins
    consider_as_foreign_keys=consider_as_foreign_keys,
  File "<string>", line 2, in join_condition
  File "<string>", line 2, in _join_condition
  File "/Users/timgilboy/recipes_v3/venv/lib/python3.6/site-packages/sqlalchemy/util/deprecations.py", line 128, in warned
    return fn(*args, **kwargs)
  File "/Users/timgilboy/recipes_v3/venv/lib/python3.6/site-packages/sqlalchemy/sql/selectable.py", line 947, in _join_condition
    % (a.description, b.description, hint)
sqlalchemy.exc.NoForeignKeysError: Can't find any foreign key relationships between 'collections2' and 'recipeCollections'.

During handling of the above exception, another exception occurred:

Traceback (most recent call last):
  File "/Users/timgilboy/recipes_v3/venv/lib/python3.6/site-packages/flask/app.py", line 2446, in wsgi_app
    response = self.full_dispatch_request()
  File "/Users/timgilboy/recipes_v3/venv/lib/python3.6/site-packages/flask/app.py", line 1951, in full_dispatch_request
    rv = self.handle_user_exception(e)
  File "/Users/timgilboy/recipes_v3/venv/lib/python3.6/site-packages/flask/app.py", line 1815, in handle_user_exception
    return self.handle_http_exception(e)
  File "/Users/timgilboy/recipes_v3/venv/lib/python3.6/site-packages/flask/app.py", line 1743, in handle_http_exception
    return handler(e)
  File "/Users/timgilboy/recipes_v3/recipe-box/app/errors/handlers.py", line 7, in not_found_error
    return render_template('errors/404.html'), 404
  File "/Users/timgilboy/recipes_v3/venv/lib/python3.6/site-packages/flask/templating.py", line 136, in render_template
    ctx.app.update_template_context(context)
  File "/Users/timgilboy/recipes_v3/venv/lib/python3.6/site-packages/flask/app.py", line 838, in update_template_context
    context.update(func())
  File "/Users/timgilboy/recipes_v3/venv/lib/python3.6/site-packages/flask_login/utils.py", line 368, in _user_context_processor
    return dict(current_user=_get_user())
  File "/Users/timgilboy/recipes_v3/venv/lib/python3.6/site-packages/flask_login/utils.py", line 335, in _get_user
    current_app.login_manager._load_user()
  File "/Users/timgilboy/recipes_v3/venv/lib/python3.6/site-packages/flask_login/login_manager.py", line 359, in _load_user
    return self.reload_user()
  File "/Users/timgilboy/recipes_v3/venv/lib/python3.6/site-packages/flask_login/login_manager.py", line 321, in reload_user
    user = self.user_callback(user_id)
  File "/Users/timgilboy/recipes_v3/recipe-box/app/models.py", line 74, in load_user
    return User.query.get(int(id))
  File "/Users/timgilboy/recipes_v3/venv/lib/python3.6/site-packages/flask_sqlalchemy/__init__.py", line 517, in __get__
    mapper = orm.class_mapper(type)
  File "/Users/timgilboy/recipes_v3/venv/lib/python3.6/site-packages/sqlalchemy/orm/base.py", line 441, in class_mapper
    mapper = _inspect_mapped_class(class_, configure=configure)
  File "/Users/timgilboy/recipes_v3/venv/lib/python3.6/site-packages/sqlalchemy/orm/base.py", line 420, in _inspect_mapped_class
    mapper._configure_all()
  File "/Users/timgilboy/recipes_v3/venv/lib/python3.6/site-packages/sqlalchemy/orm/mapper.py", line 1337, in _configure_all
    configure_mappers()
  File "/Users/timgilboy/recipes_v3/venv/lib/python3.6/site-packages/sqlalchemy/orm/mapper.py", line 3229, in configure_mappers
    mapper._post_configure_properties()
  File "/Users/timgilboy/recipes_v3/venv/lib/python3.6/site-packages/sqlalchemy/orm/mapper.py", line 1947, in _post_configure_properties
    prop.init()
  File "/Users/timgilboy/recipes_v3/venv/lib/python3.6/site-packages/sqlalchemy/orm/interfaces.py", line 196, in init
    self.do_init()
  File "/Users/timgilboy/recipes_v3/venv/lib/python3.6/site-packages/sqlalchemy/orm/relationships.py", line 1861, in do_init
    self._setup_join_conditions()
  File "/Users/timgilboy/recipes_v3/venv/lib/python3.6/site-packages/sqlalchemy/orm/relationships.py", line 1941, in _setup_join_conditions
    can_be_synced_fn=self._columns_are_mapped,
  File "/Users/timgilboy/recipes_v3/venv/lib/python3.6/site-packages/sqlalchemy/orm/relationships.py", line 2246, in __init__
    self._determine_joins()
  File "/Users/timgilboy/recipes_v3/venv/lib/python3.6/site-packages/sqlalchemy/orm/relationships.py", line 2373, in _determine_joins
    "expressions." % (self.prop, self.secondary)
sqlalchemy.exc.NoForeignKeysError: Could not determine join condition between parent/child tables on relationship Recipe2.collections2 - there are no foreign keys linking these tables via secondary table 'recipeCollections'.  Ensure that referencing columns are associated with a ForeignKey or ForeignKeyConstraint, or specify 'primaryjoin' and 'secondaryjoin' expressions.
2019-09-28 18:56:04,337 INFO: Recipe book startup [in /Users/timgilboy/recipes_v3/recipe-box/app/__init__.py:77]
2019-09-28 18:56:08,647 INFO: Recipe book startup [in /Users/timgilboy/recipes_v3/recipe-box/app/__init__.py:77]
2019-09-28 18:56:14,678 INFO: Recipe book startup [in /Users/timgilboy/recipes_v3/recipe-box/app/__init__.py:77]
2019-09-28 18:56:14,794 INFO: Recipe book startup [in /Users/timgilboy/recipes_v3/recipe-box/app/__init__.py:77]
2019-09-28 18:56:14,801 INFO: Recipe book startup [in /Users/timgilboy/recipes_v3/recipe-box/app/__init__.py:77]
2019-09-28 18:56:14,817 INFO: Recipe book startup [in /Users/timgilboy/recipes_v3/recipe-box/app/__init__.py:77]
