2019-09-28 06:53:48,917 INFO: Recipe book startup [in /Users/timgilboy/recipes_v3/recipe-box/app/__init__.py:77]
2019-09-28 17:45:05,026 INFO: Recipe book startup [in /Users/timgilboy/recipes_v3/recipe-box/app/__init__.py:77]
2019-09-28 17:45:05,034 INFO: Recipe book startup [in /Users/timgilboy/recipes_v3/recipe-box/app/__init__.py:77]
2019-09-28 18:10:46,813 INFO: Recipe book startup [in /Users/timgilboy/recipes_v3/recipe-box/app/__init__.py:77]
2019-09-28 18:10:46,822 INFO: Recipe book startup [in /Users/timgilboy/recipes_v3/recipe-box/app/__init__.py:77]
2019-09-28 18:10:46,845 INFO: Recipe book startup [in /Users/timgilboy/recipes_v3/recipe-box/app/__init__.py:77]
2019-09-28 18:52:27,738 INFO: Recipe book startup [in /Users/timgilboy/recipes_v3/recipe-box/app/__init__.py:77]
2019-09-28 18:52:35,407 INFO: Recipe book startup [in /Users/timgilboy/recipes_v3/recipe-box/app/__init__.py:77]
2019-09-28 18:52:43,629 INFO: Recipe book startup [in /Users/timgilboy/recipes_v3/recipe-box/app/__init__.py:77]
2019-09-28 18:52:43,636 INFO: Recipe book startup [in /Users/timgilboy/recipes_v3/recipe-box/app/__init__.py:77]
2019-09-28 18:52:43,639 INFO: Recipe book startup [in /Users/timgilboy/recipes_v3/recipe-box/app/__init__.py:77]
2019-09-28 18:52:43,654 INFO: Recipe book startup [in /Users/timgilboy/recipes_v3/recipe-box/app/__init__.py:77]
2019-09-28 18:52:50,652 ERROR: Exception on /index [GET] [in /Users/timgilboy/recipes_v3/venv/lib/python3.6/site-packages/flask/app.py:1891]
Traceback (most recent call last):
  File "/Users/timgilboy/recipes_v3/venv/lib/python3.6/site-packages/sqlalchemy/orm/relationships.py", line 2361, in _determine_joins
    consider_as_foreign_keys=consider_as_foreign_keys,
  File "<string>", line 2, in join_condition
  File "<string>", line 2, in _join_condition
  File "/Users/timgilboy/recipes_v3/venv/lib/python3.6/site-packages/sqlalchemy/util/deprecations.py", line 128, in warned
    return fn(*args, **kwargs)
  File "/Users/timgilboy/recipes_v3/venv/lib/python3.6/site-packages/sqlalchemy/sql/selectable.py", line 947, in _join_condition
    % (a.description, b.description, hint)
sqlalchemy.exc.NoForeignKeysError: Can't find any foreign key relationships between 'recipe2' and 'recipe__steps'.

During handling of the above exception, another exception occurred:

Traceback (most recent call last):
  File "/Users/timgilboy/recipes_v3/venv/lib/python3.6/site-packages/flask/app.py", line 2446, in wsgi_app
    response = self.full_dispatch_request()
  File "/Users/timgilboy/recipes_v3/venv/lib/python3.6/site-packages/flask/app.py", line 1951, in full_dispatch_request
    rv = self.handle_user_exception(e)
  File "/Users/timgilboy/recipes_v3/venv/lib/python3.6/site-packages/flask/app.py", line 1820, in handle_user_exception
    reraise(exc_type, exc_value, tb)
  File "/Users/timgilboy/recipes_v3/venv/lib/python3.6/site-packages/flask/_compat.py", line 39, in reraise
    raise value
  File "/Users/timgilboy/recipes_v3/venv/lib/python3.6/site-packages/flask/app.py", line 1949, in full_dispatch_request
    rv = self.dispatch_request()
  File "/Users/timgilboy/recipes_v3/venv/lib/python3.6/site-packages/flask/app.py", line 1935, in dispatch_request
    return self.view_functions[rule.endpoint](**req.view_args)
  File "/Users/timgilboy/recipes_v3/recipe-box/app/main/routes.py", line 21, in index
    recipeList = Recipe.query.limit(3).all()
  File "/Users/timgilboy/recipes_v3/venv/lib/python3.6/site-packages/flask_sqlalchemy/__init__.py", line 517, in __get__
    mapper = orm.class_mapper(type)
  File "/Users/timgilboy/recipes_v3/venv/lib/python3.6/site-packages/sqlalchemy/orm/base.py", line 441, in class_mapper
    mapper = _inspect_mapped_class(class_, configure=configure)
  File "/Users/timgilboy/recipes_v3/venv/lib/python3.6/site-packages/sqlalchemy/orm/base.py", line 420, in _inspect_mapped_class
    mapper._configure_all()
  File "/Users/timgilboy/recipes_v3/venv/lib/python3.6/site-packages/sqlalchemy/orm/mapper.py", line 1337, in _configure_all
    configure_mappers()
  File "/Users/timgilboy/recipes_v3/venv/lib/python3.6/site-packages/sqlalchemy/orm/mapper.py", line 3229, in configure_mappers
    mapper._post_configure_properties()
  File "/Users/timgilboy/recipes_v3/venv/lib/python3.6/site-packages/sqlalchemy/orm/mapper.py", line 1947, in _post_configure_properties
    prop.init()
  File "/Users/timgilboy/recipes_v3/venv/lib/python3.6/site-packages/sqlalchemy/orm/interfaces.py", line 196, in init
    self.do_init()
  File "/Users/timgilboy/recipes_v3/venv/lib/python3.6/site-packages/sqlalchemy/orm/relationships.py", line 1861, in do_init
    self._setup_join_conditions()
  File "/Users/timgilboy/recipes_v3/venv/lib/python3.6/site-packages/sqlalchemy/orm/relationships.py", line 1941, in _setup_join_conditions
    can_be_synced_fn=self._columns_are_mapped,
  File "/Users/timgilboy/recipes_v3/venv/lib/python3.6/site-packages/sqlalchemy/orm/relationships.py", line 2246, in __init__
    self._determine_joins()
  File "/Users/timgilboy/recipes_v3/venv/lib/python3.6/site-packages/sqlalchemy/orm/relationships.py", line 2383, in _determine_joins
    "specify a 'primaryjoin' expression." % self.prop
sqlalchemy.exc.NoForeignKeysError: Could not determine join condition between parent/child tables on relationship Recipe2.Instructions - there are no foreign keys linking these tables.  Ensure that referencing columns are associated with a ForeignKey or ForeignKeyConstraint, or specify a 'primaryjoin' expression.
