2019-09-18 18:47:57,696 ERROR: Exception on / [GET] [in /Users/timgilboy/recipes_v3/venv/lib/python3.6/site-packages/flask/app.py:1891]
Traceback (most recent call last):
  File "/Users/timgilboy/recipes_v3/venv/lib/python3.6/site-packages/flask/app.py", line 2446, in wsgi_app
    response = self.full_dispatch_request()
  File "/Users/timgilboy/recipes_v3/venv/lib/python3.6/site-packages/flask/app.py", line 1951, in full_dispatch_request
    rv = self.handle_user_exception(e)
  File "/Users/timgilboy/recipes_v3/venv/lib/python3.6/site-packages/flask/app.py", line 1820, in handle_user_exception
    reraise(exc_type, exc_value, tb)
  File "/Users/timgilboy/recipes_v3/venv/lib/python3.6/site-packages/flask/_compat.py", line 39, in reraise
    raise value
  File "/Users/timgilboy/recipes_v3/venv/lib/python3.6/site-packages/flask/app.py", line 1949, in full_dispatch_request
    rv = self.dispatch_request()
  File "/Users/timgilboy/recipes_v3/venv/lib/python3.6/site-packages/flask/app.py", line 1935, in dispatch_request
    return self.view_functions[rule.endpoint](**req.view_args)
  File "/Users/timgilboy/recipes_v3/recipe-box/app/main/routes.py", line 19, in index
    recipeList = Recipe.query.limit(3).all()
  File "/Users/timgilboy/recipes_v3/venv/lib/python3.6/site-packages/flask_sqlalchemy/__init__.py", line 517, in __get__
    mapper = orm.class_mapper(type)
  File "/Users/timgilboy/recipes_v3/venv/lib/python3.6/site-packages/sqlalchemy/orm/base.py", line 441, in class_mapper
    mapper = _inspect_mapped_class(class_, configure=configure)
  File "/Users/timgilboy/recipes_v3/venv/lib/python3.6/site-packages/sqlalchemy/orm/base.py", line 420, in _inspect_mapped_class
    mapper._configure_all()
  File "/Users/timgilboy/recipes_v3/venv/lib/python3.6/site-packages/sqlalchemy/orm/mapper.py", line 1337, in _configure_all
    configure_mappers()
  File "/Users/timgilboy/recipes_v3/venv/lib/python3.6/site-packages/sqlalchemy/orm/mapper.py", line 3229, in configure_mappers
    mapper._post_configure_properties()
  File "/Users/timgilboy/recipes_v3/venv/lib/python3.6/site-packages/sqlalchemy/orm/mapper.py", line 1947, in _post_configure_properties
    prop.init()
  File "/Users/timgilboy/recipes_v3/venv/lib/python3.6/site-packages/sqlalchemy/orm/interfaces.py", line 196, in init
    self.do_init()
  File "/Users/timgilboy/recipes_v3/venv/lib/python3.6/site-packages/sqlalchemy/orm/relationships.py", line 1860, in do_init
    self._process_dependent_arguments()
  File "/Users/timgilboy/recipes_v3/venv/lib/python3.6/site-packages/sqlalchemy/orm/relationships.py", line 1922, in _process_dependent_arguments
    self.target = self.entity.persist_selectable
  File "/Users/timgilboy/recipes_v3/venv/lib/python3.6/site-packages/sqlalchemy/util/langhelpers.py", line 855, in __get__
    obj.__dict__[self.__name__] = result = self.fget(obj)
  File "/Users/timgilboy/recipes_v3/venv/lib/python3.6/site-packages/sqlalchemy/orm/relationships.py", line 1845, in entity
    % (self.key, type(argument))
sqlalchemy.exc.ArgumentError: relationship 'Ingredients' expects a class or a mapper argument (received: <class 'sqlalchemy.sql.schema.Table'>)
2019-09-18 18:47:59,779 ERROR: Exception on / [GET] [in /Users/timgilboy/recipes_v3/venv/lib/python3.6/site-packages/flask/app.py:1891]
Traceback (most recent call last):
  File "/Users/timgilboy/recipes_v3/venv/lib/python3.6/site-packages/flask/app.py", line 2446, in wsgi_app
    response = self.full_dispatch_request()
  File "/Users/timgilboy/recipes_v3/venv/lib/python3.6/site-packages/flask/app.py", line 1951, in full_dispatch_request
    rv = self.handle_user_exception(e)
  File "/Users/timgilboy/recipes_v3/venv/lib/python3.6/site-packages/flask/app.py", line 1820, in handle_user_exception
    reraise(exc_type, exc_value, tb)
  File "/Users/timgilboy/recipes_v3/venv/lib/python3.6/site-packages/flask/_compat.py", line 39, in reraise
    raise value
  File "/Users/timgilboy/recipes_v3/venv/lib/python3.6/site-packages/flask/app.py", line 1949, in full_dispatch_request
    rv = self.dispatch_request()
  File "/Users/timgilboy/recipes_v3/venv/lib/python3.6/site-packages/flask/app.py", line 1935, in dispatch_request
    return self.view_functions[rule.endpoint](**req.view_args)
  File "/Users/timgilboy/recipes_v3/recipe-box/app/main/routes.py", line 19, in index
    recipeList = Recipe.query.limit(3).all()
  File "/Users/timgilboy/recipes_v3/venv/lib/python3.6/site-packages/flask_sqlalchemy/__init__.py", line 517, in __get__
    mapper = orm.class_mapper(type)
  File "/Users/timgilboy/recipes_v3/venv/lib/python3.6/site-packages/sqlalchemy/orm/base.py", line 441, in class_mapper
    mapper = _inspect_mapped_class(class_, configure=configure)
  File "/Users/timgilboy/recipes_v3/venv/lib/python3.6/site-packages/sqlalchemy/orm/base.py", line 420, in _inspect_mapped_class
    mapper._configure_all()
  File "/Users/timgilboy/recipes_v3/venv/lib/python3.6/site-packages/sqlalchemy/orm/mapper.py", line 1337, in _configure_all
    configure_mappers()
  File "/Users/timgilboy/recipes_v3/venv/lib/python3.6/site-packages/sqlalchemy/orm/mapper.py", line 3225, in configure_mappers
    raise e
sqlalchemy.exc.InvalidRequestError: One or more mappers failed to initialize - can't proceed with initialization of other mappers. Triggering mapper: 'mapped class Recipe->recipe'. Original exception was: relationship 'Ingredients' expects a class or a mapper argument (received: <class 'sqlalchemy.sql.schema.Table'>)
2019-09-18 18:48:36,134 INFO: Recipe book startup [in /Users/timgilboy/recipes_v3/recipe-box/app/__init__.py:77]
2019-09-18 18:48:39,584 INFO: Recipe book startup [in /Users/timgilboy/recipes_v3/recipe-box/app/__init__.py:77]
2019-09-18 18:48:43,639 INFO: Recipe book startup [in /Users/timgilboy/recipes_v3/recipe-box/app/__init__.py:77]
2019-09-18 18:48:53,232 INFO: Recipe book startup [in /Users/timgilboy/recipes_v3/recipe-box/app/__init__.py:77]
2019-09-18 18:48:53,238 INFO: Recipe book startup [in /Users/timgilboy/recipes_v3/recipe-box/app/__init__.py:77]
2019-09-18 18:48:53,297 INFO: Recipe book startup [in /Users/timgilboy/recipes_v3/recipe-box/app/__init__.py:77]
2019-09-18 18:48:53,306 INFO: Recipe book startup [in /Users/timgilboy/recipes_v3/recipe-box/app/__init__.py:77]
2019-09-18 18:48:54,800 ERROR: Exception on / [GET] [in /Users/timgilboy/recipes_v3/venv/lib/python3.6/site-packages/flask/app.py:1891]
Traceback (most recent call last):
  File "/Users/timgilboy/recipes_v3/venv/lib/python3.6/site-packages/flask/app.py", line 2446, in wsgi_app
    response = self.full_dispatch_request()
  File "/Users/timgilboy/recipes_v3/venv/lib/python3.6/site-packages/flask/app.py", line 1951, in full_dispatch_request
    rv = self.handle_user_exception(e)
  File "/Users/timgilboy/recipes_v3/venv/lib/python3.6/site-packages/flask/app.py", line 1820, in handle_user_exception
    reraise(exc_type, exc_value, tb)
  File "/Users/timgilboy/recipes_v3/venv/lib/python3.6/site-packages/flask/_compat.py", line 39, in reraise
    raise value
  File "/Users/timgilboy/recipes_v3/venv/lib/python3.6/site-packages/flask/app.py", line 1949, in full_dispatch_request
    rv = self.dispatch_request()
  File "/Users/timgilboy/recipes_v3/venv/lib/python3.6/site-packages/flask/app.py", line 1935, in dispatch_request
    return self.view_functions[rule.endpoint](**req.view_args)
  File "/Users/timgilboy/recipes_v3/recipe-box/app/main/routes.py", line 19, in index
    recipeList = Recipe.query.limit(3).all()
  File "/Users/timgilboy/recipes_v3/venv/lib/python3.6/site-packages/flask_sqlalchemy/__init__.py", line 517, in __get__
    mapper = orm.class_mapper(type)
  File "/Users/timgilboy/recipes_v3/venv/lib/python3.6/site-packages/sqlalchemy/orm/base.py", line 441, in class_mapper
    mapper = _inspect_mapped_class(class_, configure=configure)
  File "/Users/timgilboy/recipes_v3/venv/lib/python3.6/site-packages/sqlalchemy/orm/base.py", line 420, in _inspect_mapped_class
    mapper._configure_all()
  File "/Users/timgilboy/recipes_v3/venv/lib/python3.6/site-packages/sqlalchemy/orm/mapper.py", line 1337, in _configure_all
    configure_mappers()
  File "/Users/timgilboy/recipes_v3/venv/lib/python3.6/site-packages/sqlalchemy/orm/mapper.py", line 3229, in configure_mappers
    mapper._post_configure_properties()
  File "/Users/timgilboy/recipes_v3/venv/lib/python3.6/site-packages/sqlalchemy/orm/mapper.py", line 1947, in _post_configure_properties
    prop.init()
  File "/Users/timgilboy/recipes_v3/venv/lib/python3.6/site-packages/sqlalchemy/orm/interfaces.py", line 196, in init
    self.do_init()
  File "/Users/timgilboy/recipes_v3/venv/lib/python3.6/site-packages/sqlalchemy/orm/relationships.py", line 1860, in do_init
    self._process_dependent_arguments()
  File "/Users/timgilboy/recipes_v3/venv/lib/python3.6/site-packages/sqlalchemy/orm/relationships.py", line 1922, in _process_dependent_arguments
    self.target = self.entity.persist_selectable
  File "/Users/timgilboy/recipes_v3/venv/lib/python3.6/site-packages/sqlalchemy/util/langhelpers.py", line 855, in __get__
    obj.__dict__[self.__name__] = result = self.fget(obj)
  File "/Users/timgilboy/recipes_v3/venv/lib/python3.6/site-packages/sqlalchemy/orm/relationships.py", line 1845, in entity
    % (self.key, type(argument))
sqlalchemy.exc.ArgumentError: relationship 'Ingredients' expects a class or a mapper argument (received: <class 'sqlalchemy.sql.schema.Table'>)
